<?xml version="1.0"?>
<robot name="agri_arm">
  <material name="blue">
    <color rgba="0.0 0.0 0.8 1.0"/>
  </material>
  <material name="white">
    <color rgba="1.0 1.0 1.0 1.0"/>
  </material>

  <link name="robot_base">
    <visual>
      <geometry>
        <box size="0.6 0.4 0.1"/>
      </geometry>
      <material name="white"/>
    </visual>
  </link>

  <link name="first_link">
    <visual>
      <geometry>
        <cylinder length="0.6" radius="0.03"/>
      </geometry>
      <origin rpy="0 0 0" xyz="0 0 0.3"/>
      <material name="blue"/>
    </visual>
  </link>


  <link name="second_link">
    <visual>
      <geometry>
        <cylinder length="0.6" radius="0.03"/>
      </geometry>
      <origin rpy="0 0 0" xyz="0 0 0.3"/>
      <material name="blue"/>
    </visual>
  </link>

  <joint name="base_to_first_arm" type="continuous">
    <parent link="robot_base"/>
    <child link="first_link"/>
    <axis xyz="0 1 0" />
    <origin xyz="0 0 0.05"/>
    
  </joint>


  <joint name="first_to_second_arm" type="continuous">
    <parent link="first_link"/>
    <child link="second_link"/>
    <axis xyz="0 1 0"/>
    <origin xyz="0 0 0.6"/>
  </joint>

  <link name="third_link">
    <visual>
      <geometry>
        <cylinder length="0.6" radius="0.03"/>
      </geometry>
      <origin rpy="0 0 0" xyz="0 0 0.3"/>
      <material name="blue"/>
    </visual>
  </link>

  <joint name="second_to_third_arm" type="continuous">
    <parent link="second_link"/>
    <child link="third_link"/>
    <axis xyz="0 1 0"/>
    <origin xyz="0 0 0.6"/>
  </joint>

  <joint name="left_gripper_joint" type="continuous">
    <origin rpy="0 0 0" xyz="0 0 0.6"/>
    <axis xyz="1 0 0"/>
    <parent link="third_link"/>
    <child link="left_gripper"/>
  </joint>

  <link name="left_gripper">
    <visual>
      <origin rpy="0 -1.5725 0" xyz="0 0 0"/>
      <geometry>
        <mesh filename="package://urdf_tutorial/meshes/l_finger.dae"/>
      </geometry>
    </visual>
  </link>

  <joint name="left_tip_joint" type="fixed">
    <parent link="left_gripper"/>
    <child link="left_tip"/>
    <axis xyz="0 1 0"/>
    <origin xyz="0 0 0.1"/>
  </joint>

  <link name="left_tip">
    <visual>
      <origin rpy="0.0 -1.5725 0" xyz="0 0 0"/>
      <geometry>
        <mesh filename="package://urdf_tutorial/meshes/l_finger_tip.dae"/>
      </geometry>
    </visual>
  </link>

  <joint name="right_gripper_joint" type="continuous">
    <origin rpy="0 0 0" xyz="0 0 0.6"/>
    <axis xyz="1 0 0"/>   	
    <parent link="third_link"/>
    <child link="right_gripper"/>
  </joint>

  <link name="right_gripper">
    <visual>
      <origin rpy="-3.1415 -1.5725 0" xyz="0 0 0"/>
      <geometry>
        <mesh filename="package://urdf_tutorial/meshes/l_finger.dae"/>
      </geometry>
    </visual>
  </link>

  <joint name="right_tip_joint" type="fixed">
    <parent link="right_gripper"/>
    <child link="right_tip"/>
    <axis xyz="0 1 0"/>
    <origin xyz="0 0 0.1"/>
  </joint>

  <link name="right_tip">
    <visual>
      <origin rpy="-3.1415 -1.5725 0" xyz="0 0 0"/>
      <geometry>
        <mesh filename="package://urdf_tutorial/meshes/l_finger_tip.dae"/>
      </geometry>
    </visual>
  </link>
</robot>

